[2023-09-13 18:44:29,092] ERROR log_exception() L1449 Exception on /user/update [PUT] - call_trace=C:\Users\biaoz\PycharmProjects\18-paiting-project\venv\lib\site-packages\flask\app.py L1449
Traceback (most recent call last):
  File "C:\Users\biaoz\PycharmProjects\18-paiting-project\venv\lib\site-packages\flask\app.py", line 2073, in wsgi_app
    response = self.full_dispatch_request()
  File "C:\Users\biaoz\PycharmProjects\18-paiting-project\venv\lib\site-packages\flask\app.py", line 1519, in full_dispatch_request
    rv = self.handle_user_exception(e)
  File "C:\Users\biaoz\PycharmProjects\18-paiting-project\venv\lib\site-packages\flask_cors\extension.py", line 165, in wrapped_function
    return cors_after_request(app.make_response(f(*args, **kwargs)))
  File "C:\Users\biaoz\PycharmProjects\18-paiting-project\venv\lib\site-packages\flask\app.py", line 1517, in full_dispatch_request
    rv = self.dispatch_request()
  File "C:\Users\biaoz\PycharmProjects\18-paiting-project\venv\lib\site-packages\flask\app.py", line 1503, in dispatch_request
    return self.ensure_sync(self.view_functions[rule.endpoint])(**req.view_args)
  File "C:\Users\biaoz\PycharmProjects\18-paiting-project\venv\lib\site-packages\flask_openapi3\scaffold.py", line 273, in wrapper
    resp = _do_wrapper(
  File "C:\Users\biaoz\PycharmProjects\18-paiting-project\venv\lib\site-packages\flask_openapi3\do_wrapper.py", line 135, in _do_wrapper
    response = func(**request_kwargs)
  File "C:\Users\biaoz\OneDrive\Documentos\mvp-comment!\mvp-comment-users\app.py", line 171, in update_user
    print(user.name)
AttributeError: 'NoneType' object has no attribute 'name'
[2023-09-13 18:44:29,112] INFO _log() L224  127.0.0.1 - - [13/Sep/2023 18:44:29] "[35m[1mPUT /user/update?mail=teste0@gmail.com HTTP/1.1[0m" 500 - - call_trace=C:\Users\biaoz\PycharmProjects\18-paiting-project\venv\lib\site-packages\werkzeug\_internal.py L224 
[2023-09-13 18:44:52,345] INFO _log() L224   * Running on all addresses (0.0.0.0)
   WARNING: This is a development server. Do not use it in a production deployment.
 * Running on http://127.0.0.1:5000
 * Running on http://10.95.8.98:5000 (Press CTRL+C to quit) - call_trace=C:\Users\biaoz\PycharmProjects\18-paiting-project\venv\lib\site-packages\werkzeug\_internal.py L224 
[2023-09-13 18:44:53,958] INFO _log() L224  127.0.0.1 - - [13/Sep/2023 18:44:53] "PUT /user/update?mail=teste0@gmail.com HTTP/1.1" 200 - - call_trace=C:\Users\biaoz\PycharmProjects\18-paiting-project\venv\lib\site-packages\werkzeug\_internal.py L224 
[2023-09-13 18:45:05,995] INFO _log() L224  127.0.0.1 - - [13/Sep/2023 18:45:05] "PUT /user/update?mail=teste10@gmail.com HTTP/1.1" 200 - - call_trace=C:\Users\biaoz\PycharmProjects\18-paiting-project\venv\lib\site-packages\werkzeug\_internal.py L224 
[2023-09-13 18:45:10,799] INFO _log() L224  127.0.0.1 - - [13/Sep/2023 18:45:10] "PUT /user/update?mail=teste10@gmail.com HTTP/1.1" 200 - - call_trace=C:\Users\biaoz\PycharmProjects\18-paiting-project\venv\lib\site-packages\werkzeug\_internal.py L224 
[2023-09-13 18:45:14,147] INFO _log() L224  127.0.0.1 - - [13/Sep/2023 18:45:14] "GET /user/all HTTP/1.1" 200 - - call_trace=C:\Users\biaoz\PycharmProjects\18-paiting-project\venv\lib\site-packages\werkzeug\_internal.py L224 
[2023-09-13 18:45:28,303] INFO _log() L224  127.0.0.1 - - [13/Sep/2023 18:45:28] "PUT /user/update?mail=teste10@gmail.com HTTP/1.1" 200 - - call_trace=C:\Users\biaoz\PycharmProjects\18-paiting-project\venv\lib\site-packages\werkzeug\_internal.py L224 
[2023-09-13 18:45:35,484] INFO _log() L224  127.0.0.1 - - [13/Sep/2023 18:45:35] "PUT /user/update?mail=teste10@gmail.com HTTP/1.1" 200 - - call_trace=C:\Users\biaoz\PycharmProjects\18-paiting-project\venv\lib\site-packages\werkzeug\_internal.py L224 
[2023-09-13 18:45:38,602] INFO _log() L224  127.0.0.1 - - [13/Sep/2023 18:45:38] "GET /user/all HTTP/1.1" 200 - - call_trace=C:\Users\biaoz\PycharmProjects\18-paiting-project\venv\lib\site-packages\werkzeug\_internal.py L224 
[2023-09-13 18:59:43,456] INFO _log() L224   * Running on all addresses (0.0.0.0)
   WARNING: This is a development server. Do not use it in a production deployment.
 * Running on http://127.0.0.1:5000
 * Running on http://10.95.8.98:5000 (Press CTRL+C to quit) - call_trace=C:\Users\biaoz\PycharmProjects\18-paiting-project\venv\lib\site-packages\werkzeug\_internal.py L224 
[2023-09-13 19:00:07,088] ERROR log_exception() L1449 Exception on /user/getID [GET] - call_trace=C:\Users\biaoz\PycharmProjects\18-paiting-project\venv\lib\site-packages\flask\app.py L1449
Traceback (most recent call last):
  File "C:\Users\biaoz\PycharmProjects\18-paiting-project\venv\lib\site-packages\sqlalchemy\engine\base.py", line 1900, in _execute_context
    self.dialect.do_execute(
  File "C:\Users\biaoz\PycharmProjects\18-paiting-project\venv\lib\site-packages\sqlalchemy\engine\default.py", line 736, in do_execute
    cursor.execute(statement, parameters)
sqlite3.OperationalError: no such column: id

The above exception was the direct cause of the following exception:

Traceback (most recent call last):
  File "C:\Users\biaoz\PycharmProjects\18-paiting-project\venv\lib\site-packages\flask\app.py", line 2073, in wsgi_app
    response = self.full_dispatch_request()
  File "C:\Users\biaoz\PycharmProjects\18-paiting-project\venv\lib\site-packages\flask\app.py", line 1519, in full_dispatch_request
    rv = self.handle_user_exception(e)
  File "C:\Users\biaoz\PycharmProjects\18-paiting-project\venv\lib\site-packages\flask_cors\extension.py", line 165, in wrapped_function
    return cors_after_request(app.make_response(f(*args, **kwargs)))
  File "C:\Users\biaoz\PycharmProjects\18-paiting-project\venv\lib\site-packages\flask\app.py", line 1517, in full_dispatch_request
    rv = self.dispatch_request()
  File "C:\Users\biaoz\PycharmProjects\18-paiting-project\venv\lib\site-packages\flask\app.py", line 1503, in dispatch_request
    return self.ensure_sync(self.view_functions[rule.endpoint])(**req.view_args)
  File "C:\Users\biaoz\PycharmProjects\18-paiting-project\venv\lib\site-packages\flask_openapi3\scaffold.py", line 109, in wrapper
    resp = _do_wrapper(
  File "C:\Users\biaoz\PycharmProjects\18-paiting-project\venv\lib\site-packages\flask_openapi3\do_wrapper.py", line 135, in _do_wrapper
    response = func(**request_kwargs)
  File "C:\Users\biaoz\OneDrive\Documentos\mvp-comment!\mvp-comment-users\app.py", line 228, in get_user_ID
    user = session.execute(stmt)
  File "C:\Users\biaoz\PycharmProjects\18-paiting-project\venv\lib\site-packages\sqlalchemy\orm\session.py", line 1712, in execute
    result = conn._execute_20(statement, params or {}, execution_options)
  File "C:\Users\biaoz\PycharmProjects\18-paiting-project\venv\lib\site-packages\sqlalchemy\engine\base.py", line 1705, in _execute_20
    return meth(self, args_10style, kwargs_10style, execution_options)
  File "C:\Users\biaoz\PycharmProjects\18-paiting-project\venv\lib\site-packages\sqlalchemy\sql\elements.py", line 333, in _execute_on_connection
    return connection._execute_clauseelement(
  File "C:\Users\biaoz\PycharmProjects\18-paiting-project\venv\lib\site-packages\sqlalchemy\engine\base.py", line 1572, in _execute_clauseelement
    ret = self._execute_context(
  File "C:\Users\biaoz\PycharmProjects\18-paiting-project\venv\lib\site-packages\sqlalchemy\engine\base.py", line 1943, in _execute_context
    self._handle_dbapi_exception(
  File "C:\Users\biaoz\PycharmProjects\18-paiting-project\venv\lib\site-packages\sqlalchemy\engine\base.py", line 2124, in _handle_dbapi_exception
    util.raise_(
  File "C:\Users\biaoz\PycharmProjects\18-paiting-project\venv\lib\site-packages\sqlalchemy\util\compat.py", line 208, in raise_
    raise exception
  File "C:\Users\biaoz\PycharmProjects\18-paiting-project\venv\lib\site-packages\sqlalchemy\engine\base.py", line 1900, in _execute_context
    self.dialect.do_execute(
  File "C:\Users\biaoz\PycharmProjects\18-paiting-project\venv\lib\site-packages\sqlalchemy\engine\default.py", line 736, in do_execute
    cursor.execute(statement, parameters)
sqlalchemy.exc.OperationalError: (sqlite3.OperationalError) no such column: id
[SQL: SELECT id FROM users WHERE name = "Mariana"]
(Background on this error at: https://sqlalche.me/e/14/e3q8)
[2023-09-13 19:00:07,101] INFO _log() L224  127.0.0.1 - - [13/Sep/2023 19:00:07] "[35m[1mGET /user/getID?name=Mariana HTTP/1.1[0m" 500 - - call_trace=C:\Users\biaoz\PycharmProjects\18-paiting-project\venv\lib\site-packages\werkzeug\_internal.py L224 
[2023-09-13 19:00:34,809] INFO _log() L224   * Running on all addresses (0.0.0.0)
   WARNING: This is a development server. Do not use it in a production deployment.
 * Running on http://127.0.0.1:5000
 * Running on http://10.95.8.98:5000 (Press CTRL+C to quit) - call_trace=C:\Users\biaoz\PycharmProjects\18-paiting-project\venv\lib\site-packages\werkzeug\_internal.py L224 
[2023-09-13 19:00:37,672] INFO _log() L224  127.0.0.1 - - [13/Sep/2023 19:00:37] "GET /user/getID?name=Mariana HTTP/1.1" 200 - - call_trace=C:\Users\biaoz\PycharmProjects\18-paiting-project\venv\lib\site-packages\werkzeug\_internal.py L224 
