[2023-09-12 17:53:04,907] ERROR log_exception() L1449 Exception on /user/get [GET] - call_trace=C:\Users\biaoz\PycharmProjects\18-paiting-project\venv\lib\site-packages\flask\app.py L1449
Traceback (most recent call last):
  File "C:\Users\biaoz\PycharmProjects\18-paiting-project\venv\lib\site-packages\flask\app.py", line 2073, in wsgi_app
    response = self.full_dispatch_request()
  File "C:\Users\biaoz\PycharmProjects\18-paiting-project\venv\lib\site-packages\flask\app.py", line 1519, in full_dispatch_request
    rv = self.handle_user_exception(e)
  File "C:\Users\biaoz\PycharmProjects\18-paiting-project\venv\lib\site-packages\flask_cors\extension.py", line 165, in wrapped_function
    return cors_after_request(app.make_response(f(*args, **kwargs)))
  File "C:\Users\biaoz\PycharmProjects\18-paiting-project\venv\lib\site-packages\flask\app.py", line 1517, in full_dispatch_request
    rv = self.dispatch_request()
  File "C:\Users\biaoz\PycharmProjects\18-paiting-project\venv\lib\site-packages\flask\app.py", line 1503, in dispatch_request
    return self.ensure_sync(self.view_functions[rule.endpoint])(**req.view_args)
  File "C:\Users\biaoz\PycharmProjects\18-paiting-project\venv\lib\site-packages\flask_openapi3\scaffold.py", line 109, in wrapper
    resp = _do_wrapper(
  File "C:\Users\biaoz\PycharmProjects\18-paiting-project\venv\lib\site-packages\flask_openapi3\do_wrapper.py", line 135, in _do_wrapper
    response = func(**request_kwargs)
  File "C:\Users\biaoz\OneDrive\Documentos\mvp-comment!\mvp-comment-users\app.py", line 121, in get_user
    user = session.query(User).filter_by(1)
TypeError: Query.filter_by() takes 1 positional argument but 2 were given
[2023-09-12 17:53:04,925] INFO _log() L224  127.0.0.1 - - [12/Sep/2023 17:53:04] "[35m[1mGET /user/get HTTP/1.1[0m" 500 - - call_trace=C:\Users\biaoz\PycharmProjects\18-paiting-project\venv\lib\site-packages\werkzeug\_internal.py L224 
[2023-09-12 17:53:30,034] INFO _log() L224   * Running on all addresses (0.0.0.0)
   WARNING: This is a development server. Do not use it in a production deployment.
 * Running on http://127.0.0.1:5000
 * Running on http://10.95.8.98:5000 (Press CTRL+C to quit) - call_trace=C:\Users\biaoz\PycharmProjects\18-paiting-project\venv\lib\site-packages\werkzeug\_internal.py L224 
[2023-09-12 17:53:31,432] ERROR log_exception() L1449 Exception on /user/get [GET] - call_trace=C:\Users\biaoz\PycharmProjects\18-paiting-project\venv\lib\site-packages\flask\app.py L1449
Traceback (most recent call last):
  File "C:\Users\biaoz\PycharmProjects\18-paiting-project\venv\lib\site-packages\flask\app.py", line 2073, in wsgi_app
    response = self.full_dispatch_request()
  File "C:\Users\biaoz\PycharmProjects\18-paiting-project\venv\lib\site-packages\flask\app.py", line 1519, in full_dispatch_request
    rv = self.handle_user_exception(e)
  File "C:\Users\biaoz\PycharmProjects\18-paiting-project\venv\lib\site-packages\flask_cors\extension.py", line 165, in wrapped_function
    return cors_after_request(app.make_response(f(*args, **kwargs)))
  File "C:\Users\biaoz\PycharmProjects\18-paiting-project\venv\lib\site-packages\flask\app.py", line 1517, in full_dispatch_request
    rv = self.dispatch_request()
  File "C:\Users\biaoz\PycharmProjects\18-paiting-project\venv\lib\site-packages\flask\app.py", line 1503, in dispatch_request
    return self.ensure_sync(self.view_functions[rule.endpoint])(**req.view_args)
  File "C:\Users\biaoz\PycharmProjects\18-paiting-project\venv\lib\site-packages\flask_openapi3\scaffold.py", line 109, in wrapper
    resp = _do_wrapper(
  File "C:\Users\biaoz\PycharmProjects\18-paiting-project\venv\lib\site-packages\flask_openapi3\do_wrapper.py", line 135, in _do_wrapper
    response = func(**request_kwargs)
  File "C:\Users\biaoz\OneDrive\Documentos\mvp-comment!\mvp-comment-users\app.py", line 121, in get_user
    user = session.query(User).filter_by(1).one()
TypeError: Query.filter_by() takes 1 positional argument but 2 were given
[2023-09-12 17:53:31,437] INFO _log() L224  127.0.0.1 - - [12/Sep/2023 17:53:31] "[35m[1mGET /user/get HTTP/1.1[0m" 500 - - call_trace=C:\Users\biaoz\PycharmProjects\18-paiting-project\venv\lib\site-packages\werkzeug\_internal.py L224 
[2023-09-12 17:53:54,312] INFO _log() L224   * Running on all addresses (0.0.0.0)
   WARNING: This is a development server. Do not use it in a production deployment.
 * Running on http://127.0.0.1:5000
 * Running on http://10.95.8.98:5000 (Press CTRL+C to quit) - call_trace=C:\Users\biaoz\PycharmProjects\18-paiting-project\venv\lib\site-packages\werkzeug\_internal.py L224 
[2023-09-12 17:53:55,910] INFO _log() L224  127.0.0.1 - - [12/Sep/2023 17:53:55] "GET /user/get HTTP/1.1" 200 - - call_trace=C:\Users\biaoz\PycharmProjects\18-paiting-project\venv\lib\site-packages\werkzeug\_internal.py L224 
[2023-09-12 17:54:16,778] INFO _log() L224   * Running on all addresses (0.0.0.0)
   WARNING: This is a development server. Do not use it in a production deployment.
 * Running on http://127.0.0.1:5000
 * Running on http://10.95.8.98:5000 (Press CTRL+C to quit) - call_trace=C:\Users\biaoz\PycharmProjects\18-paiting-project\venv\lib\site-packages\werkzeug\_internal.py L224 
[2023-09-12 17:54:18,743] ERROR log_exception() L1449 Exception on /user/get [GET] - call_trace=C:\Users\biaoz\PycharmProjects\18-paiting-project\venv\lib\site-packages\flask\app.py L1449
Traceback (most recent call last):
  File "C:\Users\biaoz\PycharmProjects\18-paiting-project\venv\lib\site-packages\flask\app.py", line 2073, in wsgi_app
    response = self.full_dispatch_request()
  File "C:\Users\biaoz\PycharmProjects\18-paiting-project\venv\lib\site-packages\flask\app.py", line 1519, in full_dispatch_request
    rv = self.handle_user_exception(e)
  File "C:\Users\biaoz\PycharmProjects\18-paiting-project\venv\lib\site-packages\flask_cors\extension.py", line 165, in wrapped_function
    return cors_after_request(app.make_response(f(*args, **kwargs)))
  File "C:\Users\biaoz\PycharmProjects\18-paiting-project\venv\lib\site-packages\flask\app.py", line 1517, in full_dispatch_request
    rv = self.dispatch_request()
  File "C:\Users\biaoz\PycharmProjects\18-paiting-project\venv\lib\site-packages\flask\app.py", line 1503, in dispatch_request
    return self.ensure_sync(self.view_functions[rule.endpoint])(**req.view_args)
  File "C:\Users\biaoz\PycharmProjects\18-paiting-project\venv\lib\site-packages\flask_openapi3\scaffold.py", line 109, in wrapper
    resp = _do_wrapper(
  File "C:\Users\biaoz\PycharmProjects\18-paiting-project\venv\lib\site-packages\flask_openapi3\do_wrapper.py", line 135, in _do_wrapper
    response = func(**request_kwargs)
  File "C:\Users\biaoz\OneDrive\Documentos\mvp-comment!\mvp-comment-users\app.py", line 121, in get_user
    user = session.query(User).filter(User.name == user_name).one()
  File "C:\Users\biaoz\PycharmProjects\18-paiting-project\venv\lib\site-packages\sqlalchemy\orm\query.py", line 2869, in one
    return self._iter().one()
  File "C:\Users\biaoz\PycharmProjects\18-paiting-project\venv\lib\site-packages\sqlalchemy\engine\result.py", line 1476, in one
    return self._only_one_row(
  File "C:\Users\biaoz\PycharmProjects\18-paiting-project\venv\lib\site-packages\sqlalchemy\engine\result.py", line 562, in _only_one_row
    raise exc.NoResultFound(
sqlalchemy.exc.NoResultFound: No row was found when one was required
[2023-09-12 17:54:18,749] INFO _log() L224  127.0.0.1 - - [12/Sep/2023 17:54:18] "[35m[1mGET /user/get HTTP/1.1[0m" 500 - - call_trace=C:\Users\biaoz\PycharmProjects\18-paiting-project\venv\lib\site-packages\werkzeug\_internal.py L224 
[2023-09-12 17:57:38,959] INFO _log() L224   * Running on all addresses (0.0.0.0)
   WARNING: This is a development server. Do not use it in a production deployment.
 * Running on http://127.0.0.1:5000
 * Running on http://10.95.8.98:5000 (Press CTRL+C to quit) - call_trace=C:\Users\biaoz\PycharmProjects\18-paiting-project\venv\lib\site-packages\werkzeug\_internal.py L224 
[2023-09-12 17:57:41,798] ERROR log_exception() L1449 Exception on /user/get [GET] - call_trace=C:\Users\biaoz\PycharmProjects\18-paiting-project\venv\lib\site-packages\flask\app.py L1449
Traceback (most recent call last):
  File "C:\Users\biaoz\PycharmProjects\18-paiting-project\venv\lib\site-packages\flask\app.py", line 2073, in wsgi_app
    response = self.full_dispatch_request()
  File "C:\Users\biaoz\PycharmProjects\18-paiting-project\venv\lib\site-packages\flask\app.py", line 1520, in full_dispatch_request
    return self.finalize_request(rv)
  File "C:\Users\biaoz\PycharmProjects\18-paiting-project\venv\lib\site-packages\flask\app.py", line 1539, in finalize_request
    response = self.make_response(rv)
  File "C:\Users\biaoz\PycharmProjects\18-paiting-project\venv\lib\site-packages\flask\app.py", line 1730, in make_response
    raise TypeError(
TypeError: The view function did not return a valid response. The return type must be a string, dict, tuple, Response instance, or WSGI callable, but it was a set.
[2023-09-12 17:57:41,800] INFO _log() L224  127.0.0.1 - - [12/Sep/2023 17:57:41] "[35m[1mGET /user/get HTTP/1.1[0m" 500 - - call_trace=C:\Users\biaoz\PycharmProjects\18-paiting-project\venv\lib\site-packages\werkzeug\_internal.py L224 
[2023-09-12 17:58:20,751] INFO _log() L224  127.0.0.1 - - [12/Sep/2023 17:58:20] "GET /user/get?name=Paula HTTP/1.1" 200 - - call_trace=C:\Users\biaoz\PycharmProjects\18-paiting-project\venv\lib\site-packages\werkzeug\_internal.py L224 
