[2023-09-12 18:19:08,364] ERROR log_exception() L1449 Exception on /user/get [GET] - call_trace=C:\Users\biaoz\PycharmProjects\18-paiting-project\venv\lib\site-packages\flask\app.py L1449
Traceback (most recent call last):
  File "C:\Users\biaoz\PycharmProjects\18-paiting-project\venv\lib\site-packages\flask\app.py", line 2073, in wsgi_app
    response = self.full_dispatch_request()
  File "C:\Users\biaoz\PycharmProjects\18-paiting-project\venv\lib\site-packages\flask\app.py", line 1519, in full_dispatch_request
    rv = self.handle_user_exception(e)
  File "C:\Users\biaoz\PycharmProjects\18-paiting-project\venv\lib\site-packages\flask_cors\extension.py", line 165, in wrapped_function
    return cors_after_request(app.make_response(f(*args, **kwargs)))
  File "C:\Users\biaoz\PycharmProjects\18-paiting-project\venv\lib\site-packages\flask\app.py", line 1517, in full_dispatch_request
    rv = self.dispatch_request()
  File "C:\Users\biaoz\PycharmProjects\18-paiting-project\venv\lib\site-packages\flask\app.py", line 1503, in dispatch_request
    return self.ensure_sync(self.view_functions[rule.endpoint])(**req.view_args)
  File "C:\Users\biaoz\PycharmProjects\18-paiting-project\venv\lib\site-packages\flask_openapi3\scaffold.py", line 109, in wrapper
    resp = _do_wrapper(
  File "C:\Users\biaoz\PycharmProjects\18-paiting-project\venv\lib\site-packages\flask_openapi3\do_wrapper.py", line 135, in _do_wrapper
    response = func(**request_kwargs)
  File "C:\Users\biaoz\OneDrive\Documentos\mvp-comment!\mvp-comment-users\app.py", line 120, in get_user
    user = session.query(User).filter_by(user_name)[0]
TypeError: Query.filter_by() takes 1 positional argument but 2 were given
[2023-09-12 18:19:08,392] INFO _log() L224  127.0.0.1 - - [12/Sep/2023 18:19:08] "[35m[1mGET /user/get?name=Paula HTTP/1.1[0m" 500 - - call_trace=C:\Users\biaoz\PycharmProjects\18-paiting-project\venv\lib\site-packages\werkzeug\_internal.py L224 
[2023-09-12 18:20:02,098] INFO _log() L224   * Running on all addresses (0.0.0.0)
   WARNING: This is a development server. Do not use it in a production deployment.
 * Running on http://127.0.0.1:5000
 * Running on http://10.95.8.98:5000 (Press CTRL+C to quit) - call_trace=C:\Users\biaoz\PycharmProjects\18-paiting-project\venv\lib\site-packages\werkzeug\_internal.py L224 
[2023-09-12 18:20:03,878] ERROR log_exception() L1449 Exception on /user/get [GET] - call_trace=C:\Users\biaoz\PycharmProjects\18-paiting-project\venv\lib\site-packages\flask\app.py L1449
Traceback (most recent call last):
  File "C:\Users\biaoz\PycharmProjects\18-paiting-project\venv\lib\site-packages\flask\app.py", line 2073, in wsgi_app
    response = self.full_dispatch_request()
  File "C:\Users\biaoz\PycharmProjects\18-paiting-project\venv\lib\site-packages\flask\app.py", line 1519, in full_dispatch_request
    rv = self.handle_user_exception(e)
  File "C:\Users\biaoz\PycharmProjects\18-paiting-project\venv\lib\site-packages\flask_cors\extension.py", line 165, in wrapped_function
    return cors_after_request(app.make_response(f(*args, **kwargs)))
  File "C:\Users\biaoz\PycharmProjects\18-paiting-project\venv\lib\site-packages\flask\app.py", line 1517, in full_dispatch_request
    rv = self.dispatch_request()
  File "C:\Users\biaoz\PycharmProjects\18-paiting-project\venv\lib\site-packages\flask\app.py", line 1503, in dispatch_request
    return self.ensure_sync(self.view_functions[rule.endpoint])(**req.view_args)
  File "C:\Users\biaoz\PycharmProjects\18-paiting-project\venv\lib\site-packages\flask_openapi3\scaffold.py", line 109, in wrapper
    resp = _do_wrapper(
  File "C:\Users\biaoz\PycharmProjects\18-paiting-project\venv\lib\site-packages\flask_openapi3\do_wrapper.py", line 135, in _do_wrapper
    response = func(**request_kwargs)
  File "C:\Users\biaoz\OneDrive\Documentos\mvp-comment!\mvp-comment-users\app.py", line 123, in get_user
    return show_user(user), 200
  File "C:\Users\biaoz\OneDrive\Documentos\mvp-comment!\mvp-comment-users\schemas\user.py", line 57, in show_user
    "id": user.id,
AttributeError: 'Query' object has no attribute 'id'
[2023-09-12 18:20:03,882] INFO _log() L224  127.0.0.1 - - [12/Sep/2023 18:20:03] "[35m[1mGET /user/get?name=Paula HTTP/1.1[0m" 500 - - call_trace=C:\Users\biaoz\PycharmProjects\18-paiting-project\venv\lib\site-packages\werkzeug\_internal.py L224 
[2023-09-12 18:21:22,645] INFO _log() L224   * Running on all addresses (0.0.0.0)
   WARNING: This is a development server. Do not use it in a production deployment.
 * Running on http://127.0.0.1:5000
 * Running on http://10.95.8.98:5000 (Press CTRL+C to quit) - call_trace=C:\Users\biaoz\PycharmProjects\18-paiting-project\venv\lib\site-packages\werkzeug\_internal.py L224 
[2023-09-12 18:21:24,304] ERROR log_exception() L1449 Exception on /user/get [GET] - call_trace=C:\Users\biaoz\PycharmProjects\18-paiting-project\venv\lib\site-packages\flask\app.py L1449
Traceback (most recent call last):
  File "C:\Users\biaoz\PycharmProjects\18-paiting-project\venv\lib\site-packages\flask\app.py", line 2073, in wsgi_app
    response = self.full_dispatch_request()
  File "C:\Users\biaoz\PycharmProjects\18-paiting-project\venv\lib\site-packages\flask\app.py", line 1519, in full_dispatch_request
    rv = self.handle_user_exception(e)
  File "C:\Users\biaoz\PycharmProjects\18-paiting-project\venv\lib\site-packages\flask_cors\extension.py", line 165, in wrapped_function
    return cors_after_request(app.make_response(f(*args, **kwargs)))
  File "C:\Users\biaoz\PycharmProjects\18-paiting-project\venv\lib\site-packages\flask\app.py", line 1517, in full_dispatch_request
    rv = self.dispatch_request()
  File "C:\Users\biaoz\PycharmProjects\18-paiting-project\venv\lib\site-packages\flask\app.py", line 1503, in dispatch_request
    return self.ensure_sync(self.view_functions[rule.endpoint])(**req.view_args)
  File "C:\Users\biaoz\PycharmProjects\18-paiting-project\venv\lib\site-packages\flask_openapi3\scaffold.py", line 109, in wrapper
    resp = _do_wrapper(
  File "C:\Users\biaoz\PycharmProjects\18-paiting-project\venv\lib\site-packages\flask_openapi3\do_wrapper.py", line 135, in _do_wrapper
    response = func(**request_kwargs)
  File "C:\Users\biaoz\OneDrive\Documentos\mvp-comment!\mvp-comment-users\app.py", line 123, in get_user
    return show_user(user), 200
  File "C:\Users\biaoz\OneDrive\Documentos\mvp-comment!\mvp-comment-users\schemas\user.py", line 57, in show_user
    "id": user.id,
AttributeError: 'Query' object has no attribute 'id'
[2023-09-12 18:21:24,310] INFO _log() L224  127.0.0.1 - - [12/Sep/2023 18:21:24] "[35m[1mGET /user/get?name=Paula HTTP/1.1[0m" 500 - - call_trace=C:\Users\biaoz\PycharmProjects\18-paiting-project\venv\lib\site-packages\werkzeug\_internal.py L224 
[2023-09-12 18:21:41,434] INFO _log() L224   * Running on all addresses (0.0.0.0)
   WARNING: This is a development server. Do not use it in a production deployment.
 * Running on http://127.0.0.1:5000
 * Running on http://10.95.8.98:5000 (Press CTRL+C to quit) - call_trace=C:\Users\biaoz\PycharmProjects\18-paiting-project\venv\lib\site-packages\werkzeug\_internal.py L224 
[2023-09-12 18:21:43,029] INFO _log() L224  127.0.0.1 - - [12/Sep/2023 18:21:43] "GET /user/get?name=Paula HTTP/1.1" 200 - - call_trace=C:\Users\biaoz\PycharmProjects\18-paiting-project\venv\lib\site-packages\werkzeug\_internal.py L224 
[2023-09-12 18:23:14,322] INFO _log() L224   * Running on all addresses (0.0.0.0)
   WARNING: This is a development server. Do not use it in a production deployment.
 * Running on http://127.0.0.1:5000
 * Running on http://10.95.8.98:5000 (Press CTRL+C to quit) - call_trace=C:\Users\biaoz\PycharmProjects\18-paiting-project\venv\lib\site-packages\werkzeug\_internal.py L224 
[2023-09-12 18:23:16,269] INFO _log() L224  127.0.0.1 - - [12/Sep/2023 18:23:16] "GET /user/get?name=Paula HTTP/1.1" 200 - - call_trace=C:\Users\biaoz\PycharmProjects\18-paiting-project\venv\lib\site-packages\werkzeug\_internal.py L224 
[2023-09-12 18:23:22,042] ERROR log_exception() L1449 Exception on /user/get [GET] - call_trace=C:\Users\biaoz\PycharmProjects\18-paiting-project\venv\lib\site-packages\flask\app.py L1449
Traceback (most recent call last):
  File "C:\Users\biaoz\PycharmProjects\18-paiting-project\venv\lib\site-packages\flask\app.py", line 2073, in wsgi_app
    response = self.full_dispatch_request()
  File "C:\Users\biaoz\PycharmProjects\18-paiting-project\venv\lib\site-packages\flask\app.py", line 1519, in full_dispatch_request
    rv = self.handle_user_exception(e)
  File "C:\Users\biaoz\PycharmProjects\18-paiting-project\venv\lib\site-packages\flask_cors\extension.py", line 165, in wrapped_function
    return cors_after_request(app.make_response(f(*args, **kwargs)))
  File "C:\Users\biaoz\PycharmProjects\18-paiting-project\venv\lib\site-packages\flask\app.py", line 1517, in full_dispatch_request
    rv = self.dispatch_request()
  File "C:\Users\biaoz\PycharmProjects\18-paiting-project\venv\lib\site-packages\flask\app.py", line 1503, in dispatch_request
    return self.ensure_sync(self.view_functions[rule.endpoint])(**req.view_args)
  File "C:\Users\biaoz\PycharmProjects\18-paiting-project\venv\lib\site-packages\flask_openapi3\scaffold.py", line 109, in wrapper
    resp = _do_wrapper(
  File "C:\Users\biaoz\PycharmProjects\18-paiting-project\venv\lib\site-packages\flask_openapi3\do_wrapper.py", line 135, in _do_wrapper
    response = func(**request_kwargs)
  File "C:\Users\biaoz\OneDrive\Documentos\mvp-comment!\mvp-comment-users\app.py", line 123, in get_user
    return show_user(user), 200
  File "C:\Users\biaoz\OneDrive\Documentos\mvp-comment!\mvp-comment-users\schemas\user.py", line 57, in show_user
    "id": user.id,
AttributeError: 'NoneType' object has no attribute 'id'
